<?xml version="1.0"?>
<sdf version="1.7">
  <world name="basic_physics_world">
    <!-- Define gravity -->
    <gravity>0 0 -9.8</gravity>

    <!-- Physics engine configuration -->
    <physics name="ode_physics" type="ode">
      <max_step_size>0.001</max_step_size>
      <real_time_factor>1.0</real_time_factor>
      <real_time_update_rate>1000</real_time_update_rate>
      <ode>
        <solver>
          <type>quick</type>
          <iters>10</iters>
          <sor>1.3</sor>
        </solver>
        <constraints>
          <cfm>0.0</cfm>
          <erp>0.2</erp>
          <contact_max_correcting_vel>100.0</contact_max_correcting_vel>
          <contact_surface_layer>0.001</contact_surface_layer>
        </constraints>
      </ode>
    </physics>

    <!-- Include a ground plane -->
    <include>
      <uri>model://ground_plane</uri>
    </include>

    <!-- Include a sun for lighting -->
    <include>
      <uri>model://sun</uri>
    </include>

    <!-- Create a simple humanoid robot model -->
    <model name="simple_humanoid">
      <!-- Torso -->
      <link name="torso">
        <inertial>
          <mass>5.0</mass>
          <inertia>
            <ixx>0.1</ixx>
            <ixy>0.0</ixy>
            <ixz>0.0</ixz>
            <iyy>0.1</iyy>
            <iyz>0.0</iyz>
            <izz>0.1</izz>
          </inertia>
        </inertial>
        <collision name="torso_collision">
          <geometry>
            <box>
              <size>0.3 0.2 0.5</size>
            </box>
          </geometry>
        </collision>
        <visual name="torso_visual">
          <geometry>
            <box>
              <size>0.3 0.2 0.5</size>
            </box>
          </geometry>
        </visual>
      </link>

      <!-- Head -->
      <link name="head">
        <inertial>
          <mass>1.0</mass>
          <inertia>
            <ixx>0.01</ixx>
            <ixy>0.0</ixy>
            <ixz>0.0</ixz>
            <iyy>0.01</iyy>
            <iyz>0.0</iyz>
            <izz>0.01</izz>
          </inertia>
        </inertial>
        <collision name="head_collision">
          <geometry>
            <sphere>
              <radius>0.1</radius>
            </sphere>
          </geometry>
        </collision>
        <visual name="head_visual">
          <geometry>
            <sphere>
              <radius>0.1</radius>
            </sphere>
          </geometry>
        </visual>
      </link>

      <!-- Joint connecting torso and head -->
      <joint name="neck_joint" type="revolute">
        <parent>torso</parent>
        <child>head</child>
        <axis>
          <xyz>0 1 0</xyz>
          <limit>
            <lower>-0.5</lower>
            <upper>0.5</upper>
            <effort>10.0</effort>
            <velocity>1.0</velocity>
          </limit>
        </axis>
        <pose>0 0 0.3 0 0 0</pose>
      </joint>

      <!-- Left arm -->
      <link name="left_upper_arm">
        <inertial>
          <mass>0.8</mass>
          <inertia>
            <ixx>0.005</ixx>
            <ixy>0.0</ixy>
            <ixz>0.0</ixz>
            <iyy>0.005</iyy>
            <iyz>0.0</iyz>
            <izz>0.002</izz>
          </inertia>
        </inertial>
        <collision name="left_upper_arm_collision">
          <geometry>
            <cylinder>
              <radius>0.05</radius>
              <length>0.3</length>
            </cylinder>
          </geometry>
        </collision>
        <visual name="left_upper_arm_visual">
          <geometry>
            <cylinder>
              <radius>0.05</radius>
              <length>0.3</length>
            </cylinder>
          </geometry>
        </visual>
      </link>

      <joint name="left_shoulder_joint" type="revolute">
        <parent>torso</parent>
        <child>left_upper_arm</child>
        <axis>
          <xyz>0 1 0</xyz>
          <limit>
            <lower>-1.57</lower>
            <upper>1.57</upper>
            <effort>15.0</effort>
            <velocity>1.0</velocity>
          </limit>
        </axis>
        <pose>-0.2 0.1 0.1 0 0 0</pose>
      </joint>

      <!-- Right arm -->
      <link name="right_upper_arm">
        <inertial>
          <mass>0.8</mass>
          <inertia>
            <ixx>0.005</ixx>
            <ixy>0.0</ixy>
            <ixz>0.0</ixz>
            <iyy>0.005</iyy>
            <iyz>0.0</iyz>
            <izz>0.002</izz>
          </inertia>
        </inertial>
        <collision name="right_upper_arm_collision">
          <geometry>
            <cylinder>
              <radius>0.05</radius>
              <length>0.3</length>
            </cylinder>
          </geometry>
        </collision>
        <visual name="right_upper_arm_visual">
          <geometry>
            <cylinder>
              <radius>0.05</radius>
              <length>0.3</length>
            </cylinder>
          </geometry>
        </visual>
      </link>

      <joint name="right_shoulder_joint" type="revolute">
        <parent>torso</parent>
        <child>right_upper_arm</child>
        <axis>
          <xyz>0 1 0</xyz>
          <limit>
            <lower>-1.57</lower>
            <upper>1.57</upper>
            <effort>15.0</effort>
            <velocity>1.0</velocity>
          </limit>
        </axis>
        <pose>0.2 0.1 0.1 0 0 0</pose>
      </joint>

      <!-- Left leg -->
      <link name="left_upper_leg">
        <inertial>
          <mass>1.2</mass>
          <inertia>
            <ixx>0.01</ixx>
            <ixy>0.0</ixy>
            <ixz>0.0</ixz>
            <iyy>0.01</iyy>
            <iyz>0.0</iyz>
            <izz>0.003</izz>
          </inertia>
        </inertial>
        <collision name="left_upper_leg_collision">
          <geometry>
            <cylinder>
              <radius>0.06</radius>
              <length>0.4</length>
            </cylinder>
          </geometry>
        </collision>
        <visual name="left_upper_leg_visual">
          <geometry>
            <cylinder>
              <radius>0.06</radius>
              <length>0.4</length>
            </cylinder>
          </geometry>
        </visual>
      </link>

      <joint name="left_hip_joint" type="revolute">
        <parent>torso</parent>
        <child>left_upper_leg</child>
        <axis>
          <xyz>0 1 0</xyz>
          <limit>
            <lower>-1.0</lower>
            <upper>1.0</upper>
            <effort>20.0</effort>
            <velocity>1.0</velocity>
          </limit>
        </axis>
        <pose>-0.1 -0.1 -0.25 0 0 0</pose>
      </joint>

      <!-- Right leg -->
      <link name="right_upper_leg">
        <inertial>
          <mass>1.2</mass>
          <inertia>
            <ixx>0.01</ixx>
            <ixy>0.0</ixy>
            <ixz>0.0</ixz>
            <iyy>0.01</iyy>
            <iyz>0.0</iyz>
            <izz>0.003</izz>
          </inertia>
        </inertial>
        <collision name="right_upper_leg_collision">
          <geometry>
            <cylinder>
              <radius>0.06</radius>
              <length>0.4</length>
            </cylinder>
          </geometry>
        </collision>
        <visual name="right_upper_leg_visual">
          <geometry>
            <cylinder>
              <radius>0.06</radius>
              <length>0.4</length>
            </cylinder>
          </geometry>
        </visual>
      </link>

      <joint name="right_hip_joint" type="revolute">
        <parent>torso</parent>
        <child>right_upper_leg</child>
        <axis>
          <xyz>0 1 0</xyz>
          <limit>
            <lower>-1.0</lower>
            <upper>1.0</upper>
            <effort>20.0</effort>
            <velocity>1.0</velocity>
          </limit>
        </axis>
        <pose>0.1 -0.1 -0.25 0 0 0</pose>
      </joint>
    </model>

    <!-- Additional objects for environment interaction -->
    <model name="falling_box">
      <pose>1 0 2 0 0 0</pose>
      <link name="link">
        <inertial>
          <mass>1.0</mass>
          <inertia>
            <ixx>0.083</ixx>
            <ixy>0.0</ixy>
            <ixz>0.0</ixz>
            <iyy>0.083</iyy>
            <iyz>0.0</iyz>
            <izz>0.083</izz>
          </inertia>
        </inertial>
        <collision name="collision">
          <geometry>
            <box>
              <size>0.3 0.3 0.3</size>
            </box>
          </geometry>
        </collision>
        <visual name="visual">
          <geometry>
            <box>
              <size>0.3 0.3 0.3</size>
            </box>
          </geometry>
        </visual>
      </link>
    </model>

    <!-- Platform obstacle -->
    <model name="platform">
      <pose>3 0 0.2 0 0 0</pose>
      <link name="link">
        <inertial>
          <mass>10.0</mass>
          <inertia>
            <ixx>5.0</ixx>
            <ixy>0.0</ixy>
            <ixz>0.0</ixz>
            <iyy>5.0</iyy>
            <iyz>0.0</iyz>
            <izz>0.5</izz>
          </inertia>
        </inertial>
        <collision name="collision">
          <geometry>
            <box>
              <size>2 2 0.4</size>
            </box>
          </geometry>
        </collision>
        <visual name="visual">
          <geometry>
            <box>
              <size>2 2 0.4</size>
            </box>
          </geometry>
        </visual>
      </link>
    </model>
  </world>
</sdf>